Failure # 1 (occurred at 2023-11-30_17-45-55)
The actor died because of an error raised in its creation task, [36mray::PPO.__init__()[39m (pid=13634, ip=127.0.0.1, actor_id=c50f2356cc2547a5206545ff01000000, repr=PPO)
  File "/Users/joykhera/Library/Python/3.9/lib/python/site-packages/ray/rllib/evaluation/worker_set.py", line 227, in _setup
    self.add_workers(
  File "/Users/joykhera/Library/Python/3.9/lib/python/site-packages/ray/rllib/evaluation/worker_set.py", line 593, in add_workers
    raise result.get()
  File "/Users/joykhera/Library/Python/3.9/lib/python/site-packages/ray/rllib/utils/actor_manager.py", line 481, in __fetch_result
    result = ray.get(r)
ray.exceptions.RayActorError: The actor died because of an error raised in its creation task, [36mray::RolloutWorker.__init__()[39m (pid=13641, ip=127.0.0.1, actor_id=e0bf160c60a6c712a652cf2201000000, repr=<ray.rllib.evaluation.rollout_worker.RolloutWorker object at 0x151188850>)
  File "/Users/joykhera/Library/Python/3.9/lib/python/site-packages/ray/rllib/evaluation/rollout_worker.py", line 525, in __init__
    self._update_policy_map(policy_dict=self.policy_dict)
  File "/Users/joykhera/Library/Python/3.9/lib/python/site-packages/ray/rllib/evaluation/rollout_worker.py", line 1727, in _update_policy_map
    self._build_policy_map(
  File "/Users/joykhera/Library/Python/3.9/lib/python/site-packages/ray/rllib/evaluation/rollout_worker.py", line 1838, in _build_policy_map
    new_policy = create_policy_for_framework(
  File "/Users/joykhera/Library/Python/3.9/lib/python/site-packages/ray/rllib/utils/policy.py", line 132, in create_policy_for_framework
    return policy_class(
  File "/Users/joykhera/Library/Python/3.9/lib/python/site-packages/ray/rllib/algorithms/ppo/ppo_tf_policy.py", line 81, in __init__
    base.__init__(
  File "/Users/joykhera/Library/Python/3.9/lib/python/site-packages/ray/rllib/policy/dynamic_tf_policy_v2.py", line 83, in __init__
    self.model = self.make_model()
  File "/Users/joykhera/Library/Python/3.9/lib/python/site-packages/ray/rllib/policy/dynamic_tf_policy_v2.py", line 218, in make_model
    return ModelCatalog.get_model_v2(
  File "/Users/joykhera/Library/Python/3.9/lib/python/site-packages/ray/rllib/models/catalog.py", line 687, in get_model_v2
    return wrapper(
  File "/Users/joykhera/Library/Python/3.9/lib/python/site-packages/ray/rllib/models/tf/visionnet.py", line 169, in __init__
    raise ValueError(
ValueError: Given `conv_filters` ([[16, [3, 3], 2], [32, [3, 3], 2], [32, [4, 4], 2]]) do not result in a [B, 1, 1, 5 (`num_outputs`)] shape (but in [Dimension(None), Dimension(2), Dimension(2), Dimension(5)])! Please adjust your Conv2D stack such that the dims 1 and 2 are both 1.

During handling of the above exception, another exception occurred:

[36mray::PPO.__init__()[39m (pid=13634, ip=127.0.0.1, actor_id=c50f2356cc2547a5206545ff01000000, repr=PPO)
  File "/Users/joykhera/Library/Python/3.9/lib/python/site-packages/ray/rllib/algorithms/algorithm.py", line 517, in __init__
    super().__init__(
  File "/Users/joykhera/Library/Python/3.9/lib/python/site-packages/ray/tune/trainable/trainable.py", line 161, in __init__
    self.setup(copy.deepcopy(self.config))
  File "/Users/joykhera/Library/Python/3.9/lib/python/site-packages/ray/rllib/algorithms/algorithm.py", line 639, in setup
    self.workers = WorkerSet(
  File "/Users/joykhera/Library/Python/3.9/lib/python/site-packages/ray/rllib/evaluation/worker_set.py", line 179, in __init__
    raise e.args[0].args[2]
ValueError: Given `conv_filters` ([[16, [3, 3], 2], [32, [3, 3], 2], [32, [4, 4], 2]]) do not result in a [B, 1, 1, 5 (`num_outputs`)] shape (but in [Dimension(None), Dimension(2), Dimension(2), Dimension(5)])! Please adjust your Conv2D stack such that the dims 1 and 2 are both 1.
